Workbook

Sheet Титул
B2: Финансовая модель продукта «ИНГОССЕМЬЯ»
B3: Кейс IngoSight 2026. Все суммы в рублях; выручка и затраты без НДС, если не указано иное.
B5: Лист | C5: Содержание
B6: Допущения | C6: Все исходные параметры по четырем сценариям, расчетные параметры, команда, инвестиции
B7: Льготы ветеранам | C7: Особые условия для ветеранов СВО и ветеранов: скидки, неценовые условия, стоимость программы
B8: Время координатора | C8: Бюджет минут координатора на семью и итог по тарифам
B9: Бюджет MVP | C9: Смета MVP на 3 месяца, проверка лимита 5 млн руб., итоги по категориям
B10: Сводка | C10: NPV, окупаемость, пиковая потребность, выручка и результат по годам для всех сценариев
B11: Юнит-экономика | C11: Маржинальный доход, LTV, CAC и окупаемость CAC на одну семью
B12: Рынок | C12: TAM, SAM и SOM
B13: Пессимистичный | C13: Помесячный расчет на 60 месяцев и налог по годам
B14: Базовый | C14: Помесячный расчет на 60 месяцев и налог по годам
B15: Оптимистичный | C15: Помесячный расчет на 60 месяцев и налог по годам
B16: Версия 1 | C16: Первая версия продукта без голосового робота: показывает, почему продукт пересобран
... B19: Риски модели | C19: Подводные камни и как они учтены
B21: Обозначения
B22: Синий шрифт: исходные данные и допущения, их можно менять
B23: Черный шрифт: формулы
B24: Зеленый шрифт: ссылка на другой лист
B25: Отрицательные значения показаны в скобках, нулевые прочерком
B26: Метки у чисел: факт (из источника), расчет (на основе фактов), допущение (команды)

Sheet Допущения
A1: Исходные данные и допущения модели
A2: Синий шрифт: исходное значение, его можно менять. Черный шрифт: формула. Столбцы сценариев без собственного значения ссылаются на базовый сценарий.
A4: Параметр | B4: Единица | C4: Пессими-стичный | D4: Базовый | E4: Оптими-стичный | F4: Версия 1 без триажа | G4: Метка | H4: Источник или обоснование
A5: 1. Общие параметры
A6: НДС | B6: доля | C6: =$D6 -> 0.22 | D6: 0.22 | E6: =$D6 -> 0.22 | F6: =$D6 -> 0.22 | G6: факт | H6: НДС 22% с 01.01.2026, НК РФ ст. 164
A7: Налог на прибыль | B7: доля | C7: =$D7 -> 0.25 | D7: 0.25 | E7: =$D7 -> 0.25 | F7: =$D7 -> 0.25 | G7: факт | H7: Налог на прибыль 25% с 2025, НК РФ ст. 284
A8: Лимит переноса убытков от налоговой базы года | B8: доля | C8: =$D8 -> 0.5 | D8: 0.5 | E8: =$D8 -> 0.5 | F8: =$D8 -> 0.5 | G8: факт | H8: Перенос убытков не более 50% базы в год, НК РФ ст. 283
A9: Коэффициент страховых взносов к ФОТ | B9: коэф. | C9: =$D9 -> 1.302 | D9: 1.302 | E9: =$D9 -> 1.302 | F9: =$D9 -> 1.302 | G9: допущение | H9: Страховые взносы 30% + 0,2% травматизм, без учета снижения выше предельной базы
A10: Ставка дисконтирования, годовая | B10: доля | C10: =$D10 -> 0.22 | D10: 0.22 | E10: =$D10 -> 0.22 | F10: =$D10 -> 0.22 | G10: допущение | H10: Ставка дисконтирования для венчурного проекта внутри страховщика
A11: Индексация зарплат в год | B11: доля | C11: =$D11 -> 0.08 | D11: 0.08 | E11: =$D11 -> 0.08 | F11: =$D11 -> 0.08 | G11: допущение | H11: Индексация зарплат в год
A12: Индексация цен подписки в год, со 2-го года | B12: доля | C12: =$D12 -> 0.07 | D12: 0.07 | E12: =$D12 -> 0.07 | F12: =$D12 -> 0.07 | G12: допущение | H12: Индексация цен подписки со 2-го года
A13: Эквайринг от суммы оплаты | B13: доля | C13: =$D13 -> 0.018 | D13: 0.018 | E13: =$D13 -> 0.018 | F13: =$D13 -> 0.018 | G13: допущение | H13: Эквайринг 1,8% от оплаты
A14: Накладные расходы от ФОТ | B14: доля | C14: =$D14 -> 0.1 | D14: 0.1 | E14: =$D14 -> 0.1 | F14: =$D14 -> 0.1 | G14: допущение | H14: Накладные (офис, HR, бухгалтерия) 10% от ФОТ
A15: Рабочих часов координатора в месяц | B15: ч | C15: =$D15 -> 165 | D15: 165 | E15: =$D15 -> 165 | F15: =$D15 -> 165 | G15: допущение | H15: Производственный календарь
A16: Доля времени на работу с семьями | B16: доля | C16: =$D16 -> 0.75 | D16: 0.75 | E16: =$D16 -> 0.75 | F16: =$D16 -> 0.75 | G16: допущение | H16: Остальное: обучение, планерки, документы
A17: Множитель покрытия смен | B17: коэф. | C17: =$D17 -> 1.2 | D17: 1.2 | E17: =$D17 -> 1.2 | F17: =$D17 -> 1.2 | G17: допущение | H17: Отпуска, больничные и смены 8-22 без выходных
... A21: Резерв на непредвиденные расходы MVP | B21: доля | C21: =$D21 -> 0.1 | D21: 0.1 | E21: =$D21 -> 0.1 | F21: =$D21 -> 0.1 | G21: допущение | H21: Резерв на непредвиденные расходы
A22: 2. Параметры сценариев
A23: Цена тарифа «Базовый» с НДС | B23: руб./мес. | C23: =$D23 -> 2490 | D23: 2490 | E23: =$D23 -> 2490 | F23: 1990 | G23: допущение | H23: Базовый: робот каждый день, координатор раз в месяц и по флагу; руб в месяц с НДС
A24: Цена тарифа «Расширенный» с НДС | B24: руб./мес. | C24: =$D24 -> 4990 | D24: 4990 | E24: =$D24 -> 4990 | F24: 3990 | G24: допущение | H24: Расширенный: координатор каждую неделю; руб в месяц с НДС
A25: Доля тарифа «Расширенный» в B2C | B25: доля | C25: 0.15 | D25: 0.25 | E25: 0.3 | F25: 0.3 | G25: допущение | H25: Доля Расширенного тарифа
A26: Покупки услуг партнеров через координатора | B26: руб./семью в мес. | C26: =$D26 -> 1500 | D26: 1500 | E26: =$D26 -> 1500 | F26: =$D26 -> 1500 | G26: допущение | H26: Услуги партнеров через координатора, руб на семью в месяц
A27: Агентская комиссия с услуг партнеров | B27: доля | C27: =$D27 -> 0.1 | D27: 0.1 | E27: =$D27 -> 0.1 | F27: =$D27 -> 0.1 | G27: допущение | H27: Агентская комиссия сервисной компании с услуг партнеров
A28: Цена опции к корпоративному ДМС с НДС | B28: руб./мес. | C28: =$D28 -> 1990 | D28: 1990 | E28: =$D28 -> 1990 | F28: 1500 | G28: допущение | H28: Опция к корпоративному ДМС, руб в месяц за активную семью, Базовый уровень
A29: CAC во внутренних каналах | B29: руб. | C29: =$D29 -> 1500 | D29: 1500 | E29: =$D29 -> 1500 | F29: =$D29 -> 1500 | G29: допущение | H29: CAC во внутренних каналах: IngoMobile, рассылки клиентам ДМС, агенты
A30: Емкость внутренних каналов | B30: семей/мес. | C30: 200 | D30: 300 | E30: 400 | F30: =$D30 -> 300 | G30: допущение | H30: Сколько новых семей в месяц могут дать внутренние каналы
A31: CAC во внешних каналах | B31: руб. | C31: 7500 | D31: 6000 | E31: 4500 | F31: =$D31 -> 6000 | G31: допущение | H31: CAC во внешних каналах: клик 50-100 руб., конверсия в оплату 1-2%
A32: Маркетинговый бюджет в 4-м месяце | B32: руб. | C32: =$D32 -> 400000 | D32: 400000 | E32: =$D32 -> 400000 | F32: =$D32 -> 400000 | G32: допущение | H32: Маркетинг в 4-м месяце, руб
A33: Рост маркетингового бюджета в месяц | B33: доля | C33: =$D33 -> 0.08 | D33: 0.08 | E33: =$D33 -> 0.08 | F33: =$D33 -> 0.08 | G33: допущение | H33: Рост маркетингового бюджета в месяц до потолка
A34: Потолок маркетингового бюджета | B34: руб./мес. | C34: =$D34 -> 2500000 | D34: 2500000 | E34: =$D34 -> 2500000 | F34: =$D34 -> 2500000 | G34: допущение | H34: Потолок маркетинга в месяц
A35: Месяц запуска партнерского канала с фондом «Защитники Отечества» | B35: месяц | C35: =$D35 -> 6 | D35: 6 | E35: =$D35 -> 6 | F35: =$D35 -> 6 | G35: допущение | H35: Начало партнерского канала с фондом «Защитники Отечества» после пилота в MVP
A36: Новых семей в месяц через партнерский канал фонда | B36: семей/мес. | C36: 20 | D36: 40 | E36: 60 | F36: =$D36 -> 40 | G36: допущение | H36: Новых семей в месяц по рекомендациям социальных координаторов фонда и ветеранских организаций
A37: Затраты на привлечение в партнерском канале | B37: руб. | C37: =$D37 -> 500 | D37: 500 | E37: =$D37 -> 500 | F37: =$D37 -> 500 | G37: допущение | H37: Затраты на привлечение в партнерском канале: материалы и обучение координаторов фонда
A38: Месяц первого корпоративного клиента | B38: месяц | C38: =$D38 -> 7 | D38: 7 | E38: =$D38 -> 7 | F38: =$D38 -> 7 | G38: допущение | H38: Первый корпоративный клиент; переговоры с месяца 3
A39: Новых корпоративных клиентов в месяц | B39: клиентов | C39: 0.5 | D39: 1 | E39: 1.5 | F39: =$D39 -> 1 | G39: допущение | H39: Новых корпоративных клиентов в месяц
A40: Сотрудников у корпоративного клиента | B40: чел. | C40: =$D40 -> 2000 | D40: 2000 | E40: =$D40 -> 2000 | F40: =$D40 -> 2000 | G40: допущение | H40: Сотрудников у корпоративного клиента
A41: Доля сотрудников, подключивших родителя | B41: доля | C41: 0.02 | D41: 0.03 | E41: 0.04 | F41: =$D41 -> 0.03 | G41: допущение | H41: Доля сотрудников, которые подключают родителя
A42: Срок разгона активации у клиента | B42: мес. | C42: =$D42 -> 3 | D42: 3 | E42: =$D42 -> 3 | F42: =$D42 -> 3 | G42: допущение | H42: Месяцев до полной активации внутри клиента
A43: Отток после первого месяца | B43: доля | C43: 0.35 | D43: 0.25 | E43: 0.18 | F43: =$D43 -> 0.25 | G43: допущение | H43: Отток после первого месяца, порог H5
A44: Отток B2C в месяц со второго месяца | B44: доля | C44: 0.08 | D44: 0.06 | E44: 0.045 | F44: =$D44 -> 0.06 | G44: допущение | H44: Отток B2C в месяц со второго месяца
...

Sheet Льготы ветеранам
A1: Особые условия для ветеранов СВО и ветеранов
A2: Льгота действует на подписку B2C. Скидка уменьшает выручку во всех сценариях; ее сумма показана на листе «Сводка».
A4: Категория | B4: Доля семей B2C | C4: Скидка с подписки | D4: Вклад в среднюю скидку | E4: Условие и обоснование
A5: Родители погибших участников СВО | B5: 0.01 | C5: 1 | D5: =B5*C5 -> 0.01 | E5: Подписка «Базовый» бесплатно: у родителя нет ребенка, который организовал бы помощь [допущение]
A6: Участники СВО на службе (оплачивают сервис для родителя) | B6: 0.03 | C6: 0.5 | D6: =B6*C6 -> 0.015 | E6: На время службы и 6 месяцев после возвращения: сами не могут звонить и ездить к родителю [допущение]
A7: Ветераны боевых действий, включая ветеранов СВО, и инвалиды войны | B7: 0.05 | C7: 0.3 | D7: =B7*C7 -> 0.015 | E7: Плательщик или родитель со статусом по 5-ФЗ «О ветеранах» (с изменениями 83-ФЗ от 21.04.2025) [допущение]
A8: Ветераны ВОВ и ветераны труда (родитель) | B8: 0.08 | C8: 0.1 | D8: =B8*C8 -> 0.008 | E8: Родитель 70+ со статусом ветерана; доля уточняется анкетой [допущение]
A9: Итого: доля семей с льготой и средняя скидка | B9: =SUM(B5:B8) -> 0.17 | D9: =SUM(D5:D8) -> 0.048 | E9: Средняя скидка применяется к чеку B2C во всех сценариях
A10: Минут координатора в месяц на семью с льготой | B10: 10 | E10: Минут координатора в месяц на семью с льготой: внеочередная запись, льготные лекарства, санаторий [допущение]
A12: Неценовые условия
A13: Условие | B13: Содержание
A14: Цена | B14: Скидки по категориям из таблицы выше; для родителей погибших участников СВО тариф «Базовый» бесплатно
A15: Навигатор льгот | B15: Координатор помогает получить положенное по закону: внеочередную медпомощь, льготные лекарства, санаторно-курортное лечение, меры региональной поддержки
A16: Приоритет | B16: Отдельная линия координаторов, прошедших курс по льготам ветеранов и работе с семьями участников СВО
A17: Психологическая поддержка | B17: Консультация психолога через телемедицину Ингосстраха для семей участников СВО
A18: Партнерство | B18: Обмен обращениями с фондом «Защитники Отечества»: социальный координатор фонда передает задачи по медпомощи родителю, ИНГОССЕМЬЯ сообщает фонду о социальных вопросах семьи
A19: Работа для ветеранов | B19: Ветераны СВО и члены семей участников СВО в приоритете при найме координаторов
A20: Проверка статуса | B20: Удостоверение проверяется при подключении; в CRM хранится только категория льготы и дата проверки
A22: Стоимость льгот для сервиса (недополученная выручка без НДС)
A23: Сценарий | B23: За 60 мес., руб. | C23: Доля выручки за 60 мес.
A24: Пессимистичный | B24: =Сводка!$B$28 -> 23946264 | C24: =B24/(SUM(Пессимистичный!$W$6:$W$65)+B24) -> 0.0424244
A25: Базовый | B25: =Сводка!$C$28 -> 46773207 | C25: =B25/(SUM(Базовый!$W$6:$W$65)+B25) -> 0.040856096
A26: Оптимистичный | B26: =Сводка!$D$28 -> 77956259 | C26: =B26/(SUM(Оптимистичный!$W$6:$W$65)+B26) -> 0.039996813
A27: Версия 1 | B27: =Сводка!$E$28 -> 38890082 | C27: =B27/(SUM('Версия 1'!$W$6:$W$65)+B27) -> 0.040932126

Sheet Время координатора
A1: Бюджет живого времени координатора на одну семью в месяц
A2: Нагрузка на координатора рассчитывается от минут, а не задается числом
A4: Тариф | B4: Операция | C4: Раз в месяц | D4: Минут на операцию | E4: Минут в месяц
A5: Базовый | B5: Плановый звонок родителю | C5: 1 | D5: 12 | E5: =C5*D5 -> 12
A6: Базовый | B6: Перезвон по флагу голосового робота | C6: 0.8 | D6: 10 | E6: =C6*D6 -> 8
A7: Базовый | B7: Организация услуги (запись, анализы, доставка) | C7: 1.2 | D7: 15 | E7: =C7*D7 -> 18
A8: Базовый | B8: Проверка отчета ребенку (черновик готовит ИИ) | C8: 1.2 | D8: 3 | E8: =C8*D8 -> 3.6
A9: Базовый | B9: Ответы ребенку в чате | C9: 1 | D9: 5 | E9: =C9*D9 -> 5
A10: Базовый | B10: Помощь с льготами ветеранов (доля семей с льготой) | C10: ='Льготы ветеранам'!$B$9 -> 0.17 | D10: ='Льготы ветеранам'!$B$10 -> 10 | E10: =C10*D10 -> 1.7
A11: Итого «Базовый» | E11: =SUM(E5:E10) -> 48.3
A12: Расширенный | B12: Плановые звонки родителю | C12: 4.3 | D12: 12 | E12: =C12*D12 -> 51.6
A13: Расширенный | B13: Перезвон по флагу голосового робота | C13: 1.2 | D13: 10 | E13: =C13*D13 -> 12
A14: Расширенный | B14: Организация услуг | C14: 2.5 | D14: 15 | E14: =C14*D14 -> 37.5
A15: Расширенный | B15: Проверка отчетов ребенку | C15: 2.5 | D15: 3 | E15: =C15*D15 -> 7.5
A16: Расширенный | B16: Ответы ребенку в чате | C16: 1 | D16: 10 | E16: =C16*D16 -> 10
A17: Расширенный | B17: Помощь с льготами ветеранов (доля семей с льготой) | C17: ='Льготы ветеранам'!$B$9 -> 0.17 | D17: ='Льготы ветеранам'!$B$10 -> 10 | E17: =C17*D17 -> 1.7
A18: Итого «Расширенный» | E18: =SUM(E12:E17) -> 120.3

Sheet Бюджет MVP
A1: Бюджет MVP на 3 месяца
A2: Итог по статье = количество x цена x месяцев x коэффициент взносов (для ФОТ)
A4: Категория | B4: Статья | C4: Кол-во | D4: Цена за ед., руб. | E4: Месяцев | F4: Взносы | G4: Итого, руб. | H4: Метка | I4: Комментарий
A5: Команда | B5: Руководитель продукта | C5: 1 | D5: 230000 | E5: 3 | F5: да | G5: =ROUND(C5*D5*E5*IF(F5="да",Допущения!$D$9,1),0) -> 898380 | H5: допущение | I5: Рыночная зарплата Москва, 1 FTE
A6: Команда | B6: Исследователь и аналитик | C6: 0.3 | D6: 170000 | E6: 3 | F6: да | G6: =ROUND(C6*D6*E6*IF(F6="да",Допущения!$D$9,1),0) -> 199206 | H6: допущение | I6: Анкеты, когорты; первые интервью проводит команда до старта
A7: Команда | B7: Разработчик бота и интеграций | C7: 0.4 | D7: 260000 | E7: 3 | F7: да | G7: =ROUND(C7*D7*E7*IF(F7="да",Допущения!$D$9,1),0) -> 406224 | H7: допущение | I7: Бот в MAX на конструкторе, CRM, телефония
A8: Команда | B8: Координаторы (3 человека) | C8: 3 | D8: 70000 | E8: 2.5 | F8: да | G8: =ROUND(C8*D8*E8*IF(F8="да",Допущения!$D$9,1),0) -> 683550 | H8: допущение | I8: Операторы ДМС регионального контакт-центра; 1-й месяц на половину ставки
A9: Команда | B9: Врач-методист (терапевт или гериатр) | C9: 0.25 | D9: 220000 | E9: 3 | F9: да | G9: =ROUND(C9*D9*E9*IF(F9="да",Допущения!$D$9,1),0) -> 214830 | H9: допущение | I9: Протоколы эскалации, супервизия
A10: Команда | B10: Юрист по ПДн и договорам | C10: 0.2 | D10: 240000 | E10: 2 | F10: да | G10: =ROUND(C10*D10*E10*IF(F10="да",Допущения!$D$9,1),0) -> 124992 | H10: допущение | I10: Согласия на медданные, договоры с партнерами
A11: Команда | B11: Дизайнер | C11: 0.2 | D11: 200000 | E11: 2 | F11: да | G11: =ROUND(C11*D11*E11*IF(F11="да",Допущения!$D$9,1),0) -> 104160 | H11: допущение | I11: Бот, лендинг, отчеты
A12: Обучение | B12: Курс по работе с пожилыми и основам гериатрии | C12: 3 | D12: 35000 | E12: 1 | F12: нет | G12: =ROUND(C12*D12*E12*IF(F12="да",Допущения!$D$9,1),0) -> 105000 | H12: допущение | I12: Внешний курс на каждого координатора
A13: Обучение | B13: Скрипты звонков и супервизия психолога | C13: 1 | D13: 60000 | E13: 1 | F13: нет | G13: =ROUND(C13*D13*E13*IF(F13="да",Допущения!$D$9,1),0) -> 60000 | H13: допущение | I13: Профилактика выгорания
A14: Обучение | B14: Обучение операторов ДМС для резерва | C14: 4 | D14: 8000 | E14: 1 | F14: нет | G14: =ROUND(C14*D14*E14*IF(F14="да",Допущения!$D$9,1),0) -> 32000 | H14: допущение | I14: Внутренний тренинг, 1 день
A15: Обучение | B15: Курс: льготы ветеранов и работа с семьями участников СВО | C15: 3 | D15: 15000 | E15: 1 | F15: нет | G15: =ROUND(C15*D15*E15*IF(F15="да",Допущения!$D$9,1),0) -> 45000 | H15: допущение | I15: 5-ФЗ «О ветеранах», региональные меры, психологические аспекты; программа с фондом «Защитники Отечества»
A16: Юридическая схема | B16: Оформление сервиса через сервисную компанию группы | C16: 1 | D16: 200000 | E16: 1 | F16: нет | G16: =ROUND(C16*D16*E16*IF(F16="да",Допущения!$D$9,1),0) -> 200000 | H16: допущение | I16: Ст. 6 закона 4015-1 ограничивает страховщика страховой деятельностью; заключение юриста, оферта, агентские договоры
... A30: Маркетинг и исследования | B30: Вознаграждение респондентам | C30: 20 | D30: 1500 | E30: 1 | F30: нет | G30: =ROUND(C30*D30*E30*IF(F30="да",Допущения!$D$9,1),0) -> 30000 | H30: допущение | I30: 20 глубинных интервью
A31: Накладные | B31: Накладные от ФОТ команды MVP | G31: =ROUND(SUMIF(F5:F30,"да",G5:G30)*Допущения!$D$14,0) -> 263134 | H31: допущение | I31: Рабочие места, HR, бухгалтерия
A32: Резерв | B32: Резерв на непредвиденные расходы | G32: =ROUND((SUM(G5:G30)+G31)*Допущения!$D$21,0) -> 443088 | H32: допущение | I32: Резерв на непредвиденные расходы
A33: Итого бюджет MVP | G33: =SUM(G5:G32) -> 4873964
A34: Лимит бюджета | G34: =Допущения!$D$20 -> 5000000 | I34: Условие кейса
A35: Запас до лимита | G35: =G34-G33 -> 126036 | I35: =IF(G35>=0,"Бюджет в пределах лимита","Превышение лимита") -> Бюджет в пределах лимита
A37: Бюджет по категориям
A38: Категория | B38: Сумма, руб. | C38: Доля
A39: Команда | B39: =SUMIF($A$5:$A$32,A39,$G$5:$G$32) -> 2631342 | C39: =B39/$G$33 -> 0.53987719
A40: Обучение | B40: =SUMIF($A$5:$A$32,A40,$G$5:$G$32) -> 242000 | C40: =B40/$G$33 -> 0.049651577
A41: Юридическая схема | B41: =SUMIF($A$5:$A$32,A41,$G$5:$G$32) -> 200000 | C41: =B41/$G$33 -> 0.041034361
A42: Лицензии и ИТ | B42: =SUMIF($A$5:$A$32,A42,$G$5:$G$32) -> 667400 | C42: =B42/$G$33 -> 0.13693166
A43: Операции | B43: =SUMIF($A$5:$A$32,A43,$G$5:$G$32) -> 97000 | C43: =B43/$G$33 -> 0.019901665
A44: Маркетинг и исследования | B44: =SUMIF($A$5:$A$32,A44,$G$5:$G$32) -> 330000 | C44: =B44/$G$33 -> 0.067706696
A45: Накладные | B45: =SUMIF($A$5:$A$32,A45,$G$5:$G$32) -> 263134 | C45: =B45/$G$33 -> 0.053987678
A46: Резерв | B46: =SUMIF($A$5:$A$32,A46,$G$5:$G$32) -> 443088 | C46: =B46/$G$33 -> 0.090909166
A47: Итого | B47: =SUM(B39:B46) -> 4873964 | C47: =SUM(C39:C46) -> 1

Sheet Сводка
A1: Сводные результаты по сценариям
A2: Горизонт 60 месяцев, NPV по месячной ставке дисконтирования
A4: Показатель | B4: Пессимистичный | C4: Базовый | D4: Оптимистичный | E4: Версия 1 без триажа
A5: NPV до налога за 36 мес., руб. | B5: =SUMPRODUCT(Пессимистичный!$AI$6:$AI$41,Пессимистичный!$AO$6:$AO$41) -> -89328769 | C5: =SUMPRODUCT(Базовый!$AI$6:$AI$41,Базовый!$AO$6:$AO$41) -> -21114552 | D5: =SUMPRODUCT(Оптимистичный!$AI$6:$AI$41,Оптимистичный!$AO$6:$AO$41) -> 66276520 | E5: =SUMPRODUCT('Версия 1'!$AI$6:$AI$41,'Версия 1'!$AO$6:$AO$41) -> -1.6994413e+08
A6: NPV после налога за 36 мес., руб. | B6: =SUMPRODUCT(Пессимистичный!$AN$6:$AN$41,Пессимистичный!$AO$6:$AO$41) -> -89328769 | C6: =SUMPRODUCT(Базовый!$AN$6:$AN$41,Базовый!$AO$6:$AO$41) -> -21953294 | D6: =SUMPRODUCT(Оптимистичный!$AN$6:$AN$41,Оптимистичный!$AO$6:$AO$41) -> 50060163 | E6: =SUMPRODUCT('Версия 1'!$AN$6:$AN$41,'Версия 1'!$AO$6:$AO$41) -> -1.6994413e+08
A7: NPV до налога за 60 мес., руб. | B7: =SUMPRODUCT(Пессимистичный!$AI$6:$AI$65,Пессимистичный!$AO$6:$AO$65) -> -1.3308264e+08 | C7: =SUMPRODUCT(Базовый!$AI$6:$AI$65,Базовый!$AO$6:$AO$65) -> 23483259 | D7: =SUMPRODUCT(Оптимистичный!$AI$6:$AI$65,Оптимистичный!$AO$6:$AO$65) -> 2.4774695e+08 | E7: =SUMPRODUCT('Версия 1'!$AI$6:$AI$65,'Версия 1'!$AO$6:$AO$65) -> -3.0781391e+08
A8: NPV после налога за 60 мес., руб. | B8: =SUMPRODUCT(Пессимистичный!$AN$6:$AN$65,Пессимистичный!$AO$6:$AO$65) -> -1.3308264e+08 | C8: =SUMPRODUCT(Базовый!$AN$6:$AN$65,Базовый!$AO$6:$AO$65) -> 15293260 | D8: =SUMPRODUCT(Оптимистичный!$AN$6:$AN$65,Оптимистичный!$AO$6:$AO$65) -> 1.9004086e+08 | E8: =SUMPRODUCT('Версия 1'!$AN$6:$AN$65,'Версия 1'!$AO$6:$AO$65) -> -3.0781391e+08
A9: NPV до налога за 60 мес. с кросс-продажами группы, руб. | B9: =SUMPRODUCT(Пессимистичный!$AI$6:$AI$65+Пессимистичный!$AK$6:$AK$65,Пессимистичный!$AO$6:$AO$65) -> -1.3133325e+08 | C9: =SUMPRODUCT(Базовый!$AI$6:$AI$65+Базовый!$AK$6:$AK$65,Базовый!$AO$6:$AO$65) -> 30113192 | D9: =SUMPRODUCT(Оптимистичный!$AI$6:$AI$65+Оптимистичный!$AK$6:$AK$65,Оптимистичный!$AO$6:$AO$65) -> 2.6402013e+08 | E9: =SUMPRODUCT('Версия 1'!$AI$6:$AI$65+'Версия 1'!$AK$6:$AK$65,'Версия 1'!$AO$6:$AO$65) -> -3.0118398e+08
A10: Пиковая потребность в деньгах, руб. | B10: =MAX(0,-MIN(Пессимистичный!$AJ$6:$AJ$65)) -> 2.2083319e+08 | C10: =MAX(0,-MIN(Базовый!$AJ$6:$AJ$65)) -> 32533857 | D10: =MAX(0,-MIN(Оптимистичный!$AJ$6:$AJ$65)) -> 18255992 | E10: =MAX(0,-MIN('Версия 1'!$AJ$6:$AJ$65)) -> 5.5299689e+08
A11: Месяц операционной безубыточности | B11: =IF(COUNT(Пессимистичный!$AP$6:$AP$65)=0,"не достигается",MIN(Пессимистичный!$AP$6:$AP$65)) -> не достигается | C11: =IF(COUNT(Базовый!$AP$6:$AP$65)=0,"не достигается",MIN(Базовый!$AP$6:$AP$65)) -> 24 | D11: =IF(COUNT(Оптимистичный!$AP$6:$AP$65)=0,"не достигается",MIN(Оптимистичный!$AP$6:$AP$65)) -> 13 | E11: =IF(COUNT('Версия 1'!$AP$6:$AP$65)=0,"не достигается",MIN('Версия 1'!$AP$6:$AP$65)) -> не достигается
A12: Месяц окупаемости (накопленный результат > 0) | B12: =IF(COUNT(Пессимистичный!$AQ$6:$AQ$65)=0,"не достигается",MIN(Пессимистичный!$AQ$6:$AQ$65)) -> не достигается | C12: =IF(COUNT(Базовый!$AQ$6:$AQ$65)=0,"не достигается",MIN(Базовый!$AQ$6:$AQ$65)) -> 43 | D12: =IF(COUNT(Оптимистичный!$AQ$6:$AQ$65)=0,"не достигается",MIN(Оптимистичный!$AQ$6:$AQ$65)) -> 21 | E12: =IF(COUNT('Версия 1'!$AQ$6:$AQ$65)=0,"не достигается",MIN('Версия 1'!$AQ$6:$AQ$65)) -> не достигается
A13: Семей на конец 36 мес. | B13: =Пессимистичный!$O$41 -> 4331.7901 | C13: =Базовый!$O$41 -> 8235.3631 | D13: =Оптимистичный!$O$41 -> 13617.66 | E13: ='Версия 1'!$O$41 -> 8235.3631
A14: Семей на конец 60 мес. | B14: =Пессимистичный!$O$65 -> 5233.807 | C14: =Базовый!$O$65 -> 10653.815 | D14: =Оптимистичный!$O$65 -> 18914.162 | E14: ='Версия 1'!$O$65 -> 10653.815
A15: Координаторов на конец 60 мес. | B15: =Пессимистичный!$R$65 -> 64 | C15: =Базовый!$R$65 -> 109 | D15: =Оптимистичный!$R$65 -> 170 | E15: ='Версия 1'!$R$65 -> 153
A16: Выручка за MVP, руб. | B16: =SUM(Пессимистичный!$W$6:$W$8) -> 292866.89 | C16: =SUM(Базовый!$W$6:$W$8) -> 316276.72 | D16: =SUM(Оптимистичный!$W$6:$W$8) -> 327981.64 | E16: =SUM('Версия 1'!$W$6:$W$8) -> 267116.07
A17: Выручка, год 1, руб. | B17: =Пессимистичный!$B$70 -> 18779931 | C17: =Базовый!$B$70 -> 31496602 | D17: =Оптимистичный!$B$70 -> 41038866 | E17: ='Версия 1'!$B$70 -> 26337800
A18: Выручка, год 2, руб. | B18: =Пессимистичный!$B$71 -> 64939175 | C18: =Базовый!$B$71 -> 1.2489503e+08 | D18: =Оптимистичный!$B$71 -> 1.9322244e+08 | E18: ='Версия 1'!$B$71 -> 1.038415e+08
A19: Выручка, год 3, руб. | B19: =Пессимистичный!$B$72 -> 1.1763414e+08 | C19: =Базовый!$B$72 -> 2.3287691e+08 | D19: =Оптимистичный!$B$72 -> 3.8485219e+08 | E19: ='Версия 1'!$B$72 -> 1.9341124e+08
A20: Выручка, год 4, руб. | B20: =Пессимистичный!$B$73 -> 1.5729593e+08 | C20: =Базовый!$B$73 -> 3.2292213e+08 | D20: =Оптимистичный!$B$73 -> 5.5921336e+08 | E20: ='Версия 1'!$B$73 -> 2.6792167e+08
A21: Выручка, год 5, руб. | B21: =Пессимистичный!$B$74 -> 1.8185011e+08 | C21: =Базовый!$B$74 -> 3.8586421e+08 | D21: =Оптимистичный!$B$74 -> 6.9277866e+08 | E21: ='Версия 1'!$B$74 -> 3.1970916e+08
A22: Операционный результат, год 1, руб. | B22: =Пессимистичный!$C$70 -> -32670499 | C22: =Базовый!$C$70 -> -24976439 | D22: =Оптимистичный!$C$70 -> -18255992 | E22: ='Версия 1'!$C$70 -> -43302772
A23: Операционный результат, год 2, руб. | B23: =Пессимистичный!$C$71 -> -40397407 | C23: =Базовый!$C$71 -> -7556528.9 | D23: =Оптимистичный!$C$71 -> 32437821 | E23: ='Версия 1'!$C$71 -> -79712783
A24: Операционный результат, год 3, руб. | B24: =Пессимистичный!$C$72 -> -50659679 | C24: =Базовый!$C$72 -> 12184223 | D24: =Оптимистичный!$C$72 -> 1.0003577e+08 | E24: ='Версия 1'!$C$72 -> -1.2193943e+08
A25: Операционный результат, год 4, руб. | B25: =Пессимистичный!$C$73 -> -48137365 | C25: =Базовый!$C$73 -> 40463904 | D25: =Оптимистичный!$C$73 -> 1.7557154e+08 | E25: ='Версия 1'!$C$73 -> -1.4498746e+08
A26: Операционный результат, год 5, руб. | B26: =Пессимистичный!$C$74 -> -48968239 | C26: =Базовый!$C$74 -> 60999135 | D26: =Оптимистичный!$C$74 -> 2.3434135e+08 | E26: ='Версия 1'!$C$74 -> -1.6305444e+08
A27: Кросс-продажи за 60 мес. (эффект группы), руб. | B27: =Пессимистичный!$H$75 -> 3257280 | C27: =Базовый!$H$75 -> 12495581 | D27: =Оптимистичный!$H$75 -> 31135755 | E27: ='Версия 1'!$H$75 -> 12495581
A28: Льготы ветеранам за 60 мес. (недополученная выручка), руб. | B28: =SUM(Пессимистичный!$AL$6:$AL$65) -> 23946264 | C28: =SUM(Базовый!$AL$6:$AL$65) -> 46773207 | D28: =SUM(Оптимистичный!$AL$6:$AL$65) -> 77956259 | E28: =SUM('Версия 1'!$AL$6:$AL$65) -> 38890082

Sheet Юнит-экономика
A1: Юнит-экономика одной семьи B2C
A2: Устоявшаяся семья, первый год, без индексации цен и зарплат
A4: Показатель | B4: Пессимистичный | C4: Базовый | D4: Оптимистичный | E4: Версия 1 без триажа
A5: Средний чек по прейскуранту с НДС, руб./мес. | B5: =Допущения!$C$70 -> 2865 | C5: =Допущения!$D$70 -> 3115 | D5: =Допущения!$E$70 -> 3240 | E5: =Допущения!$F$70 -> 2590
A6: Средняя скидка по льготам ветеранам | B6: ='Льготы ветеранам'!$D$9 -> 0.048 | C6: ='Льготы ветеранам'!$D$9 -> 0.048 | D6: ='Льготы ветеранам'!$D$9 -> 0.048 | E6: ='Льготы ветеранам'!$D$9 -> 0.048
A7: Средний чек с НДС с учетом льгот, руб./мес. | B7: =B5*(1-B6) -> 2727.48 | C7: =C5*(1-C6) -> 2965.48 | D7: =D5*(1-D6) -> 3084.48 | E7: =E5*(1-E6) -> 2465.68
A8: Средний чек без НДС, руб./мес. | B8: =B7/(1+Допущения!$C$6) -> 2235.6393 | C8: =C7/(1+Допущения!$D$6) -> 2430.7213 | D8: =D7/(1+Допущения!$E$6) -> 2528.2623 | E8: =E7/(1+Допущения!$F$6) -> 2021.0492
A9: Комиссия партнеров без НДС, руб./мес. | B9: =Допущения!$C$26*Допущения!$C$27/(1+Допущения!$C$6) -> 122.95082 | C9: =Допущения!$D$26*Допущения!$D$27/(1+Допущения!$D$6) -> 122.95082 | D9: =Допущения!$E$26*Допущения!$E$27/(1+Допущения!$E$6) -> 122.95082 | E9: =Допущения!$F$26*Допущения!$F$27/(1+Допущения!$F$6) -> 122.95082
A10: Семей «Базовый» на координатора | B10: =Допущения!$C$68 -> 98.542762 | C10: =Допущения!$D$68 -> 128.10559 | D10: =Допущения!$E$68 -> 150.71246 | E10: =Допущения!$F$68 -> 83.333333
A11: Семей «Расширенный» на координатора | B11: =Допущения!$C$69 -> 39.56455 | C11: =Допущения!$D$69 -> 51.433915 | D11: =Допущения!$E$69 -> 60.510488 | E11: =Допущения!$F$69 -> 46.296296
A12: Доля ставки координатора на семью | B12: =(1-Допущения!$C$25)/B10+Допущения!$C$25/B11 -> 0.01241697 | C12: =(1-Допущения!$D$25)/C10+Допущения!$D$25/C11 -> 0.010715152 | D12: =(1-Допущения!$E$25)/D10+Допущения!$E$25/D11 -> 0.0096024242 | E12: =(1-Допущения!$F$25)/E10+Допущения!$F$25/E11 -> 0.01488
A13: Полная стоимость координатора с супервизией, руб./мес. | B13: =Допущения!$C$47*Допущения!$C$9*(1+Допущения!$C$14)+Допущения!$C$49*Допущения!$C$9*(1+Допущения!$C$14)/Допущения!$C$48+Допущения!$C$52*(1+1/Допущения!$C$48)+Допущения!$C$51*Допущения!$C$50/12 -> 132379.5 | C13: =Допущения!$D$47*Допущения!$D$9*(1+Допущения!$D$14)+Допущения!$D$49*Допущения!$D$9*(1+Допущения!$D$14)/Допущения!$D$48+Допущения!$D$52*(1+1/Допущения!$D$48)+Допущения!$D$51*Допущения!$D$50/12 -> 118057.5 | D13: =Допущения!$E$47*Допущения!$E$9*(1+Допущения!$E$14)+Допущения!$E$49*Допущения!$E$9*(1+Допущения!$E$14)/Допущения!$E$48+Допущения!$E$52*(1+1/Допущения!$E$48)+Допущения!$E$51*Допущения!$E$50/12 -> 110896.5 | E13: =Допущения!$F$47*Допущения!$F$9*(1+Допущения!$F$14)+Допущения!$F$49*Допущения!$F$9*(1+Допущения!$F$14)/Допущения!$F$48+Допущения!$F$52*(1+1/Допущения!$F$48)+Допущения!$F$51*Допущения!$F$50/12 -> 145263.1
A14: Координатор, супервизия, накладные на семью, руб./мес. | B14: =B13*B12 -> 1643.7522 | C14: =C13*C12 -> 1265.004 | D14: =D13*D12 -> 1064.8752 | E14: =E13*E12 -> 2161.5149
A15: Прочие переменные на семью, руб./мес. | B15: =Допущения!$C$53+Допущения!$C$54+B7*Допущения!$C$13+Допущения!$C$56/1000 -> 422.09464 | C15: =Допущения!$D$53+Допущения!$D$54+C7*Допущения!$D$13+Допущения!$D$56/1000 -> 426.37864 | D15: =Допущения!$E$53+Допущения!$E$54+D7*Допущения!$E$13+Допущения!$E$56/1000 -> 428.52064 | E15: =Допущения!$F$53+Допущения!$F$54+E7*Допущения!$F$13+Допущения!$F$56/1000 -> 497.38224
A16: Маржинальный доход на семью, руб./мес. | B16: =B8+B9-B14-B15 -> 292.74328 | C16: =C8+C9-C14-C15 -> 862.28949 | D16: =D8+D9-D14-D15 -> 1157.8172 | E16: =E8+E9-E14-E15 -> -514.89717
A17: Маржинальность | B17: =B16/(B8+B9) -> 0.12411791 | C17: =C16/(C8+C9) -> 0.33766648 | D17: =D16/(D8+D9) -> 0.43671225 | E17: =E16/(E8+E9) -> -0.24015726
A18: Средний срок жизни, мес. | B18: =1+(1-Допущения!$C$43)/Допущения!$C$44 -> 9.125 | C18: =1+(1-Допущения!$D$43)/Допущения!$D$44 -> 13.5 | D18: =1+(1-Допущения!$E$43)/Допущения!$E$44 -> 19.222222 | E18: =1+(1-Допущения!$F$43)/Допущения!$F$44 -> 13.5
A19: LTV, руб. | B19: =B16*B18 -> 2671.2825 | C19: =C16*C18 -> 11640.908 | D19: =D16*D18 -> 22255.82 | E19: =E16*E18 -> -6951.1118
A20: CAC при полном бюджете (смесь каналов), руб. | B20: =Допущения!$C$34/(Допущения!$C$30+(Допущения!$C$34-Допущения!$C$30*Допущения!$C$29)/Допущения!$C$31) -> 5067.5676 | C20: =Допущения!$D$34/(Допущения!$D$30+(Допущения!$D$34-Допущения!$D$30*Допущения!$D$29)/Допущения!$D$31) -> 3896.1039 | D20: =Допущения!$E$34/(Допущения!$E$30+(Допущения!$E$34-Допущения!$E$30*Допущения!$E$29)/Допущения!$E$31) -> 3040.5405 | E20: =Допущения!$F$34/(Допущения!$F$30+(Допущения!$F$34-Допущения!$F$30*Допущения!$F$29)/Допущения!$F$31) -> 3896.1039
A21: LTV/CAC | B21: =B19/B20 -> 0.52713307 | C21: =C19/C20 -> 2.9878331 | D21: =D19/D20 -> 7.319692 | E21: =E19/E20 -> -1.7841187
A22: Окупаемость CAC, мес. | B22: =IF(B16>0,B20/B16,"не окупается") -> 17.310619 | C22: =IF(C16>0,C20/C16,"не окупается") -> 4.5183247 | D22: =IF(D16>0,D20/D16,"не окупается") -> 2.6260972 | E22: =IF(E16>0,E20/E16,"не окупается") -> не окупается

Sheet Рынок
A1: Оценка размера рынка (порядок величины)
A2: Базовый сценарий
A4: Показатель | B4: Значение | C4: Метка | D4: Источник или обоснование
A5: Люди 65+ в РФ | B5: 25800000 | C5: факт | D5: Росстат через Демоскоп, 01.01.2025
A6: Доля с хроническими заболеваниями | B6: 0.54 | C6: факт | D6: Минздрав (Мурашко), 07.2026, для старше трудоспособного возраста, используем как приближение
A7: Доля живущих отдельно от взрослых детей | B7: 0.6 | C7: допущение | D7: Проверяется анкетой (вопрос 3)
A8: Доля, где ребенок работает и сам координирует медпомощь | B8: 0.7 | C8: допущение | D8: Проверяется анкетой (вопросы 4-5)
A9: Доля в городах 250 тыс.+ с доходом, позволяющим платить 2,5 тыс. в месяц | B9: 0.35 | C9: допущение | D9: Оценка команды, проверяется тестом цены
A10: TAM, семей | B10: =B5*B6*B7*B8 -> 5851440 | C10: расчет | D10: Произведение долей
A11: TAM, руб. в год | B11: =B10*Допущения!$D$71*12 -> 2.0822794e+11 | C11: расчет | D11: TAM x средний чек с НДС x 12
A12: SAM, семей | B12: =B10*B9 -> 2048004 | C12: расчет | D12: TAM x доля платежеспособных в городах 250 тыс.+
A13: SAM, руб. в год | B13: =B12*Допущения!$D$71*12 -> 7.2879779e+10 | C13: расчет | D13: SAM x средний чек с НДС x 12
A14: SOM на 60 мес., семей (базовый сценарий) | B14: =Сводка!$C$14 -> 10653.815 | C14: расчет | D14: Лист «Сводка»
A15: Доля SOM от SAM | B15: =B14/B12 -> 0.0052020479 | C15: расчет | D15: SOM / SAM

Sheet Пессимистичный
A1: Помесячный расчет: сценарий «Пессимистичный»
A2: Суммы в рублях без НДС. Месяцы 1-3: MVP. Налог на прибыль начисляется в последнем месяце года.
A5: Месяц | B5: Год | C5: Фаза | D5: Индекс зарплат | E5: Индекс цен | F5: Средний чек B2C с НДС, руб. | G5: Маркетинг, руб. | H5: Новые семьи: внутренние каналы | I5: Новые семьи: внешние каналы | J5: Новые семьи: канал фонда «Защитники Отечества» | K5: Новые семьи B2C | L5: Семьи B2C | M5: Приток B2B2C | N5: Семьи B2B2C | O5: Всего семей | P5: Семьи «Расши-ренный» | Q5: Семьи «Базовый» и B2B2C | R5: Координа-торы, чел. | S5: Супер-визоры, чел. | T5: Выручка: подписка B2C, руб. | U5: Выручка: B2B2C, руб. | V5: Выручка: комиссия партнеров, руб. | W5: Выручка всего, руб. | X5: Партнерский канал фонда, руб. | Y5: ФОТ координаторов и супервизоров, руб. | Z5: Обучение новых координаторов, руб. | AA5: Переменные расходы на семьи, руб. | AB5: Рабочие места, руб. | AC5: Постоянная команда, руб. | AD5: Накладные, руб. | AE5: Размещение и юрлицо, руб. | AF5: Инвестиции, руб. | AG5: Бюджет MVP, руб. | AH5: Расходы всего, руб. | AI5: Операционный результат, руб. | AJ5: Накопленный результат, руб. | AK5: Кросс-продажи (эффект группы), руб. | AL5: Льготы ветеранам: недополученная выручка, руб. | AM5: Налог на прибыль, руб. | AN5: Денежный поток после налога, руб. | AO5: Коэффициент дисконтирования | AP5: Признак безубыточности (месяц) | AQ5: Признак окупаемости (месяц)
A6: 1 | B6: =INT((A6-1)/12)+1 -> 1 | C6: MVP | D6: =(1+Допущения!$C$11)^(B6-1) -> 1 | E6: =(1+Допущения!$C$12)^(B6-1) -> 1 | F6: =Допущения!$C$71*E6 -> 2727.48 | G6: 0 | H6: 0 | I6: 0 | J6: 0 | K6: =Допущения!$B$78-0 -> 0 | L6: =Допущения!$B$78 -> 0 | M6: 0 | N6: 0 | O6: =L6+N6 -> 0 | P6: =L6*Допущения!$C$25 -> 0 | Q6: =L6*(1-Допущения!$C$25)+N6 -> 0 | R6: =IF(A6>1,Допущения!$C$18,0) -> 0 | S6: 0 | T6: =L6*Допущения!$C$60*F6/(1+Допущения!$C$6) -> 0 | U6: =N6*Допущения!$C$28*E6/(1+Допущения!$C$6) -> 0 | V6: =O6*Допущения!$C$26*Допущения!$C$27/(1+Допущения!$C$6) -> 0 | W6: =T6+U6+V6 -> 0 | X6: 0 | Y6: 0 | Z6: 0 | AA6: 0 | AB6: 0 | AC6: 0 | AD6: 0 | AE6: 0 | AF6: 0 | AG6: ='Бюджет MVP'!$G$33/Допущения!$C$19 -> 1624654.7 | AH6: =G6+SUM(X6:AG6) -> 1624654.7 | AI6: =W6-AH6 -> -1624654.7 | AJ6: =AI6 -> -1624654.7 | AK6: 0 | AL6: =T6*Допущения!$C$72 -> 0 | AM6: =IF(MOD(A6,12)=0,INDEX($F$70:$F$74,B6),0) -> 0 | AN6: =AI6-AM6 -> -1624654.7 | AO6: =1/(1+Допущения!$C$74)^A6 -> 0.98356564 | AP6: =IF(AND(A6>Допущения!$C$19,MIN(AI6:AI$65)>0),A6,"") | AQ6: =IF(MIN(AJ6:AJ$65)>0,A6,"")
A7: 2 | B7: =INT((A7-1)/12)+1 -> 1 | C7: MVP | D7: =(1+Допущения!$C$11)^(B7-1) -> 1 | E7: =(1+Допущения!$C$12)^(B7-1) -> 1 | F7: =Допущения!$C$71*E7 -> 2727.48 | G7: 0 | H7: 0 | I7: 0 | J7: 0 | K7: =Допущения!$B$79-Допущения!$B$78 -> 50 | L7: =Допущения!$B$79 -> 50 | M7: 0 | N7: 0 | O7: =L7+N7 -> 50 | P7: =L7*Допущения!$C$25 -> 7.5 | Q7: =L7*(1-Допущения!$C$25)+N7 -> 42.5 | R7: =IF(A7>1,Допущения!$C$18,0) -> 3 | S7: 0 | T7: =L7*Допущения!$C$60*F7/(1+Допущения!$C$6) -> 67069.18 | U7: =N7*Допущения!$C$28*E7/(1+Допущения!$C$6) -> 0 | V7: =O7*Допущения!$C$26*Допущения!$C$27/(1+Допущения!$C$6) -> 6147.541 | W7: =T7+U7+V7 -> 73216.721 | X7: 0 | Y7: 0 | Z7: 0 | AA7: 0 | AB7: 0 | AC7: 0 | AD7: 0 | AE7: 0 | AF7: 0 | AG7: ='Бюджет MVP'!$G$33/Допущения!$C$19 -> 1624654.7 | AH7: =G7+SUM(X7:AG7) -> 1624654.7 | AI7: =W7-AH7 -> -1551437.9 | AJ7: =AJ6+AI7 -> -3176092.6 | AK7: 0 | AL7: =T7*Допущения!$C$72 -> 3381.6393 | AM7: =IF(MOD(A7,12)=0,INDEX($F$70:$F$74,B7),0) -> 0 | AN7: =AI7-AM7 -> -1551437.9 | AO7: =1/(1+Допущения!$C$74)^A7 -> 0.96740136 | AP7: =IF(AND(A7>Допущения!$C$19,MIN(AI7:AI$65)>0),A7,"") | AQ7: =IF(MIN(AJ7:AJ$65)>0,A7,"")
A8: 3 | B8: =INT((A8-1)/12)+1 -> 1 | C8: MVP | D8: =(1+Допущения!$C$11)^(B8-1) -> 1 | E8: =(1+Допущения!$C$12)^(B8-1) -> 1 | F8: =Допущения!$C$71*E8 -> 2727.48 | G8: 0 | H8: 0 | I8: 0 | J8: 0 | K8: =Допущения!$B$80-Допущения!$B$79 -> 100 | L8: =Допущения!$B$80 -> 150 | M8: 0 | N8: 0 | O8: =L8+N8 -> 150 | P8: =L8*Допущения!$C$25 -> 22.5 | Q8: =L8*(1-Допущения!$C$25)+N8 -> 127.5 | R8: =IF(A8>1,Допущения!$C$18,0) -> 3 | S8: 0 | T8: =L8*Допущения!$C$60*F8/(1+Допущения!$C$6) -> 201207.54 | U8: =N8*Допущения!$C$28*E8/(1+Допущения!$C$6) -> 0 | V8: =O8*Допущения!$C$26*Допущения!$C$27/(1+Допущения!$C$6) -> 18442.623 | W8: =T8+U8+V8 -> 219650.16 | X8: 0 | Y8: 0 | Z8: 0 | AA8: 0 | AB8: 0 | AC8: 0 | AD8: 0 | AE8: 0 | AF8: 0 | AG8: ='Бюджет MVP'!$G$33/Допущения!$C$19 -> 1624654.7 | AH8: =G8+SUM(X8:AG8) -> 1624654.7 | AI8: =W8-AH8 -> -1405004.5 | AJ8: =AJ7+AI8 -> -4581097.1 | AK8: 0 | AL8: =T8*Допущения!$C$72 -> 10144.918 | AM8: =IF(MOD(A8,12)=0,INDEX($F$70:$F$74,B8),0) -> 0 | AN8: =AI8-AM8 -> -1405004.5 | AO8: =1/(1+Допущения!$C$74)^A8 -> 0.95150274 | AP8: =IF(AND(A8>Допущения!$C$19,MIN(AI8:AI$65)>0),A8,"") | AQ8: =IF(MIN(AJ8:AJ$65)>0,A8,"")
A9: 4 | B9: =INT((A9-1)/12)+1 -> 1 | C9: Масштабирование | D9: =(1+Допущения!$C$11)^(B9-1) -> 1 | E9: =(1+Допущения!$C$12)^(B9-1) -> 1 | F9: =Допущения!$C$71*E9 -> 2727.48 | G9: =Допущения!$C$32 -> 400000 | H9: =MIN(Допущения!$C$30,G9/Допущения!$C$29) -> 200 | I9: =MAX(0,G9-H9*Допущения!$C$29)/Допущения!$C$31 -> 13.333333 | J9: =IF(A9>=Допущения!$C$35,Допущения!$C$36,0) -> 0 | K9: =H9+I9+J9 -> 213.33333 | L9: =(L8-K8)*(1-Допущения!$C$44)+K8*(1-Допущения!$C$43)+K9 -> 324.33333 | M9: =IF(A9>=Допущения!$C$38,Допущения!$C$73/Допущения!$C$42*MIN(Допущения!$C$42,A9-Допущения!$C$38+1),0) -> 0 | N9: =N8*(1-Допущения!$C$45)+M9 -> 0 | O9: =L9+N9 -> 324.33333 | P9: =L9*Допущения!$C$25 -> 48.65 | Q9: =L9*(1-Допущения!$C$25)+N9 -> 275.68333 | R9: =MAX(Допущения!$C$18,ROUNDUP(Q9/Допущения!$C$68+P9/Допущения!$C$69,0)) -> 5 | S9: =ROUNDUP(R9/Допущения!$C$48,0) -> 1 | T9: =L9*F9/(1+Допущения!$C$6) -> 725092.36 | U9: =N9*Допущения!$C$28*E9/(1+Допущения!$C$6) -> 0 | V9: =O9*Допущения!$C$26*Допущения!$C$27/(1+Допущения!$C$6) -> 39877.049 | W9: =T9+U9+V9 -> 764969.41 | X9: =J9*Допущения!$C$37 -> 0 | Y9: =(R9*Допущения!$C$47+S9*Допущения!$C$49)*D9*Допущения!$C$9 -> 664020 | Z9: =(MAX(0,R9-R8)+R9*Допущения!$C$50/12)*Допущения!$C$51*D9 -> 148750 | AA9: =O9*(Допущения!$C$53+Допущения!$C$54)+(L9*F9+N9*Допущения!$C$28*E9)*Допущения!$C$13 -> 134304.69 | AB9: =(R9+S9)*Допущения!$C$52 -> 16200 | AC9: =SUMPRODUCT(Допущения!$B$84:$B$91,Допущения!$C$84:$C$91,--(Допущения!$D$84:$D$91<=A9))*D9*Допущения!$C$9 -> 1132740 | AD9: =(AC9+Y9)*Допущения!$C$14 -> 179676 | AE9: =Допущения!$C$55+Допущения!$C$56*O9/1000+Допущения!$C$57 -> 142594.67 | AF9: =SUMIF(Допущения!$B$95:$B$103,A9,Допущения!$C$95:$C$103) -> 1000000 | AG9: 0 | AH9: =G9+SUM(X9:AG9) -> 3818285.4 | AI9: =W9-AH9 -> -3053316 | AJ9: =AJ8+AI9 -> -7634413.1 | AK9: =O9*Допущения!$C$58*Допущения!$C$59 -> 5351.5 | AL9: =T9*Допущения!$C$72 -> 36559.279 | AM9: =IF(MOD(A9,12)=0,INDEX($F$70:$F$74,B9),0) -> 0 | AN9: =AI9-AM9 -> -3053316 | AO9: =1/(1+Допущения!$C$74)^A9 -> 0.9358654 | AP9: =IF(AND(A9>Допущения!$C$19,MIN(AI9:AI$65)>0),A9,"") | AQ9: =IF(MIN(AJ9:AJ$65)>0,A9,"")
A10: 5 | B10: =INT((A10-1)/12)+1 -> 1 | C10: Масштабирование | D10: =(1+Допущения!$C$11)^(B10-1) -> 1 | E10: =(1+Допущения!$C$12)^(B10-1) -> 1 | F10: =Допущения!$C$71*E10 -> 2727.48 | G10: =MIN(G9*(1+Допущения!$C$33),Допущения!$C$34) -> 432000 | H10: =MIN(Допущения!$C$30,G10/Допущения!$C$29) -> 200 | I10: =MAX(0,G10-H10*Допущения!$C$29)/Допущения!$C$31 -> 17.6 | J10: =IF(A10>=Допущения!$C$35,Допущения!$C$36,0) -> 0 | K10: =H10+I10+J10 -> 217.6 | L10: =(L9-K9)*(1-Допущения!$C$44)+K9*(1-Допущения!$C$43)+K10 -> 458.38667 | M10: =IF(A10>=Допущения!$C$38,Допущения!$C$73/Допущения!$C$42*MIN(Допущения!$C$42,A10-Допущения!$C$38+1),0) -> 0 | N10: =N9*(1-Допущения!$C$45)+M10 -> 0 | O10: =L10+N10 -> 458.38667 | P10: =L10*Допущения!$C$25 -> 68.758 | Q10: =L10*(1-Допущения!$C$25)+N10 -> 389.62867 | R10: =MAX(Допущения!$C$18,ROUNDUP(Q10/Допущения!$C$68+P10/Допущения!$C$69,0)) -> 6 | S10: =ROUNDUP(R10/Допущения!$C$48,0) -> 1 | T10: =L10*F10/(1+Допущения!$C$6) -> 1024787.3 | U10: =N10*Допущения!$C$28*E10/(1+Допущения!$C$6) -> 0 | V10: =O10*Допущения!$C$26*Допущения!$C$27/(1+Допущения!$C$6) -> 56359.016 | W10: =T10+U10+V10 -> 1081146.3 | X10: =J10*Допущения!$C$37 -> 0 | Y10: =(R10*Допущения!$C$47+S10*Допущения!$C$49)*D10*Допущения!$C$9 -> 768180 | Z10: =(MAX(0,R10-R9)+R10*Допущения!$C$50/12)*Допущения!$C$51*D10 -> 80500 | AA10: =O10*(Допущения!$C$53+Допущения!$C$54)+(L10*F10+N10*Допущения!$C$28*E10)*Допущения!$C$13 -> 189815.46 | AB10: =(R10+S10)*Допущения!$C$52 -> 18900 | AC10: =SUMPRODUCT(Допущения!$B$84:$B$91,Допущения!$C$84:$C$91,--(Допущения!$D$84:$D$91<=A10))*D10*Допущения!$C$9 -> 1132740 | AD10: =(AC10+Y10)*Допущения!$C$14 -> 190092 | AE10: =Допущения!$C$55+Допущения!$C$56*O10/1000+Допущения!$C$57 -> 143667.09 | AF10: =SUMIF(Допущения!$B$95:$B$103,A10,Допущения!$C$95:$C$103) -> 1000000 | AG10: 0 | AH10: =G10+SUM(X10:AG10) -> 3955894.6 | AI10: =W10-AH10 -> -2874748.3 | AJ10: =AJ9+AI10 -> -10509161 | AK10: =O10*Допущения!$C$58*Допущения!$C$59 -> 7563.38 | AL10: =T10*Допущения!$C$72 -> 51669.946 | AM10: =IF(MOD(A10,12)=0,INDEX($F$70:$F$74,B10),0) -> 0 | AN10: =AI10-AM10 -> -2874748.3 | AO10: =1/(1+Допущения!$C$74)^A10 -> 0.92048505 | AP10: =IF(AND(A10>Допущения!$C$19,MIN(AI10:AI$65)>0),A10,"") | AQ10: =IF(MIN(AJ10:AJ$65)>0,A10,"")
A11: 6 | B11: =INT((A11-1)/12)+1 -> 1 | C11: Масштабирование | D11: =(1+Допущения!$C$11)^(B11-1) -> 1 | E11: =(1+Допущения!$C$12)^(B11-1) -> 1 | F11: =Допущения!$C$71*E11 -> 2727.48 | G11: =MIN(G10*(1+Допущения!$C$33),Допущения!$C$34) -> 466560 | H11: =MIN(Допущения!$C$30,G11/Допущения!$C$29) -> 200 | I11: =MAX(0,G11-H11*Допущения!$C$29)/Допущения!$C$31 -> 22.208 | J11: =IF(A11>=Допущения!$C$35,Допущения!$C$36,0) -> 20 | K11: =H11+I11+J11 -> 242.208 | L11: =(L10-K10)*(1-Допущения!$C$44)+K10*(1-Допущения!$C$43)+K11 -> 605.17173 | M11: =IF(A11>=Допущения!$C$38,Допущения!$C$73/Допущения!$C$42*MIN(Допущения!$C$42,A11-Допущения!$C$38+1),0) -> 0 | N11: =N10*(1-Допущения!$C$45)+M11 -> 0 | O11: =L11+N11 -> 605.17173 | P11: =L11*Допущения!$C$25 -> 90.77576 | Q11: =L11*(1-Допущения!$C$25)+N11 -> 514.39597 | R11: =MAX(Допущения!$C$18,ROUNDUP(Q11/Допущения!$C$68+P11/Допущения!$C$69,0)) -> 8 | S11: =ROUNDUP(R11/Допущения!$C$48,0) -> 1 | T11: =L11*F11/(1+Допущения!$C$6) -> 1352945.7 | U11: =N11*Допущения!$C$28*E11/(1+Допущения!$C$6) -> 0 | V11: =O11*Допущения!$C$26*Допущения!$C$27/(1+Допущения!$C$6) -> 74406.361 | W11: =T11+U11+V11 -> 1427352.1 | X11: =J11*Допущения!$C$37 -> 10000 | Y11: =(R11*Допущения!$C$47+S11*Допущения!$C$49)*D11*Допущения!$C$9 -> 976500 | Z11: =(MAX(0,R11-R10)+R11*Допущения!$C$50/12)*Допущения!$C$51*D11 -> 154000 | AA11: =O11*(Допущения!$C$53+Допущения!$C$54)+(L11*F11+N11*Допущения!$C$28*E11)*Допущения!$C$13 -> 250598.37 | AB11: =(R11+S11)*Допущения!$C$52 -> 24300 | AC11: =SUMPRODUCT(Допущения!$B$84:$B$91,Допущения!$C$84:$C$91,--(Допущения!$D$84:$D$91<=A11))*D11*Допущения!$C$9 -> 1627500 | AD11: =(AC11+Y11)*Допущения!$C$14 -> 260400 | AE11: =Допущения!$C$55+Допущения!$C$56*O11/1000+Допущения!$C$57 -> 144841.37 | AF11: =SUMIF(Допущения!$B$95:$B$103,A11,Допущения!$C$95:$C$103) -> 1000000 | AG11: 0 | AH11: =G11+SUM(X11:AG11) -> 4914699.7 | AI11: =W11-AH11 -> -3487347.6 | AJ11: =AJ10+AI11 -> -13996509 | AK11: =O11*Допущения!$C$58*Допущения!$C$59 -> 9985.3336 | AL11: =T11*Допущения!$C$72 -> 68215.751 | AM11: =IF(MOD(A11,12)=0,INDEX($F$70:$F$74,B11),0) -> 0 | AN11: =AI11-AM11 -> -3487347.6 | AO11: =1/(1+Допущения!$C$74)^A11 -> 0.90535746 | AP11: =IF(AND(A11>Допущения!$C$19,MIN(AI11:AI$65)>0),A11,"") | AQ11: =IF(MIN(AJ11:AJ$65)>0,A11,"")
A12: 7 | B12: =INT((A12-1)/12)+1 -> 1 | C12: Масштабирование | D12: =(1+Допущения!$C$11)^(B12-1) -> 1 | E12: =(1+Допущения!$C$12)^(B12-1) -> 1 | F12: =Допущения!$C$71*E12 -> 2727.48 | G12: =MIN(G11*(1+Допущения!$C$33),Допущения!$C$34) -> 503884.8 | H12: =MIN(Допущения!$C$30,G12/Допущения!$C$29) -> 200 | I12: =MAX(0,G12-H12*Допущения!$C$29)/Допущения!$C$31 -> 27.18464 | J12: =IF(A12>=Допущения!$C$35,Допущения!$C$36,0) -> 20 | K12: =H12+I12+J12 -> 247.18464 | L12: =(L11-K11)*(1-Допущения!$C$44)+K11*(1-Допущения!$C$43)+K12 -> 738.54647 | M12: =IF(A12>=Допущения!$C$38,Допущения!$C$73/Допущения!$C$42*MIN(Допущения!$C$42,A12-Допущения!$C$38+1),0) -> 6.6666667 | N12: =N11*(1-Допущения!$C$45)+M12 -> 6.6666667 | O12: =L12+N12 -> 745.21314 | P12: =L12*Допущения!$C$25 -> 110.78197 | Q12: =L12*(1-Допущения!$C$25)+N12 -> 634.43117 | R12: =MAX(Допущения!$C$18,ROUNDUP(Q12/Допущения!$C$68+P12/Допущения!$C$69,0)) -> 10 | S12: =ROUNDUP(R12/Допущения!$C$48,0) -> 1 | T12: =L12*F12/(1+Допущения!$C$6) -> 1651123.6 | U12: =N12*Допущения!$C$28*E12/(1+Допущения!$C$6) -> 10874.317 | V12: =O12*Допущения!$C$26*Допущения!$C$27/(1+Допущения!$C$6) -> 91624.567 | W12: =T12+U12+V12 -> 1753622.4 | X12: =J12*Допущения!$C$37 -> 10000 | Y12: =(R12*Допущения!$C$47+S12*Допущения!$C$49)*D12*Допущения!$C$9 -> 1184820 | Z12: =(MAX(0,R12-R11)+R12*Допущения!$C$50/12)*Допущения!$C$51*D12 -> 157500 | AA12: =O12*(Допущения!$C$53+Допущения!$C$54)+(L12*F12+N12*Допущения!$C$28*E12)*Допущения!$C$13 -> 308500.27 | AB12: =(R12+S12)*Допущения!$C$52 -> 29700 | AC12: =SUMPRODUCT(Допущения!$B$84:$B$91,Допущения!$C$84:$C$91,--(Допущения!$D$84:$D$91<=A12))*D12*Допущения!$C$9 -> 1627500 | AD12: =(AC12+Y12)*Допущения!$C$14 -> 281232 | AE12: =Допущения!$C$55+Допущения!$C$56*O12/1000+Допущения!$C$57 -> 145961.71 | AF12: =SUMIF(Допущения!$B$95:$B$103,A12,Допущения!$C$95:$C$103) -> 500000 | AG12: 0 | AH12: =G12+SUM(X12:AG12) -> 4749098.8 | AI12: =W12-AH12 -> -2995476.3 | AJ12: =AJ11+AI12 -> -16991985 | AK12: =O12*Допущения!$C$58*Допущения!$C$59 -> 12296.017 | AL12: =T12*Допущения!$C$72 -> 83249.927 | AM12: =IF(MOD(A12,12)=0,INDEX($F$70:$F$74,B12),0) -> 0 | AN12: =AI12-AM12 -> -2995476.3 | AO12: =1/(1+Допущения!$C$74)^A12 -> 0.89047849 | AP12: =IF(AND(A12>Допущения!$C$19,MIN(AI12:AI$65)>0),A12,"") | AQ12: =IF(MIN(AJ12:AJ$65)>0,A12,"")
A13: 8 | B13: =INT((A13-1)/12)+1 -> 1 | C13: Масштабирование | D13: =(1+Допущения!$C$11)^(B13-1) -> 1 | E13: =(1+Допущения!$C$12)^(B13-1) -> 1 | F13: =Допущения!$C$71*E13 -> 2727.48 | G13: =MIN(G12*(1+Допущения!$C$33),Допущения!$C$34) -> 544195.58 | H13: =MIN(Допущения!$C$30,G13/Допущения!$C$29) -> 200 | I13: =MAX(0,G13-H13*Допущения!$C$29)/Допущения!$C$31 -> 32.559411 | J13: =IF(A13>=Допущения!$C$35,Допущения!$C$36,0) -> 20 | K13: =H13+I13+J13 -> 252.55941 | L13: =(L12-K12)*(1-Допущения!$C$44)+K12*(1-Допущения!$C$43)+K13 -> 865.28232 | M13: =IF(A13>=Допущения!$C$38,Допущения!$C$73/Допущения!$C$42*MIN(Допущения!$C$42,A13-Допущения!$C$38+1),0) -> 13.333333 | N13: =N12*(1-Допущения!$C$45)+M13 -> 19.866667 | O13: =L13+N13 -> 885.14898 | P13: =L13*Допущения!$C$25 -> 129.79235 | Q13: =L13*(1-Допущения!$C$25)+N13 -> 755.35663 | R13: =MAX(Допущения!$C$18,ROUNDUP(Q13/Допущения!$C$68+P13/Допущения!$C$69,0)) -> 11 | S13: =ROUNDUP(R13/Допущения!$C$48,0) -> 1 | T13: =L13*F13/(1+Допущения!$C$6) -> 1934459.2 | U13: =N13*Допущения!$C$28*E13/(1+Допущения!$C$6) -> 32405.464 | V13: =O13*Допущения!$C$26*Допущения!$C$27/(1+Допущения!$C$6) -> 108829.79 | W13: =T13+U13+V13 -> 2075694.4 | X13: =J13*Допущения!$C$37 -> 10000 | Y13: =(R13*Допущения!$C$47+S13*Допущения!$C$49)*D13*Допущения!$C$9 -> 1288980 | Z13: =(MAX(0,R13-R12)+R13*Допущения!$C$50/12)*Допущения!$C$51*D13 -> 89250 | AA13: =O13*(Допущения!$C$53+Допущения!$C$54)+(L13*F13+N13*Допущения!$C$28*E13)*Допущения!$C$13 -> 366271.73 | AB13: =(R13+S13)*Допущения!$C$52 -> 32400 | AC13: =SUMPRODUCT(Допущения!$B$84:$B$91,Допущения!$C$84:$C$91,--(Допущения!$D$84:$D$91<=A13))*D13*Допущения!$C$9 -> 1627500 | AD13: =(AC13+Y13)*Допущения!$C$14 -> 291648 | AE13: =Допущения!$C$55+Допущения!$C$56*O13/1000+Допущения!$C$57 -> 147081.19 | AF13: =SUMIF(Допущения!$B$95:$B$103,A13,Допущения!$C$95:$C$103) -> 500000 | AG13: 0 | AH13: =G13+SUM(X13:AG13) -> 4897326.5 | AI13: =W13-AH13 -> -2821632.1 | AJ13: =AJ12+AI13 -> -19813617 | AK13: =O13*Допущения!$C$58*Допущения!$C$59 -> 14604.958 | AL13: =T13*Допущения!$C$72 -> 97535.757 | AM13: =IF(MOD(A13,12)=0,INDEX($F$70:$F$74,B13),0) -> 0 | AN13: =AI13-AM13 -> -2821632.1 | AO13: =1/(1+Допущения!$C$74)^A13 -> 0.87584404 | AP13: =IF(AND(A13>Допущения!$C$19,MIN(AI13:AI$65)>0),A13,"") | AQ13: =IF(MIN(AJ13:AJ$65)>0,A13,"")
A14: 9 | B14: =INT((A14-1)/12)+1 -> 1 | C14: Масштабирование | D14: =(1+Допущения!$C$11)^(B14-1) -> 1 | E14: =(1+Допущения!$C$12)^(B14-1) -> 1 | F14: =Допущения!$C$71*E14 -> 2727.48 | G14: =MIN(G13*(1+Допущения!$C$33),Допущения!$C$34) -> 587731.23 | H14: =MIN(Допущения!$C$30,G14/Допущения!$C$29) -> 200 | I14: =MAX(0,G14-H14*Допущения!$C$29)/Допущения!$C$31 -> 38.364164 | J14: =IF(A14>=Допущения!$C$35,Допущения!$C$36,0) -> 20 | K14: =H14+I14+J14 -> 258.36416 | L14: =(L13-K13)*(1-Допущения!$C$44)+K13*(1-Допущения!$C$43)+K14 -> 986.23285 | M14: =IF(A14>=Допущения!$C$38,Допущения!$C$73/Допущения!$C$42*MIN(Допущения!$C$42,A14-Допущения!$C$38+1),0) -> 20 | N14: =N13*(1-Допущения!$C$45)+M14 -> 39.469333 | O14: =L14+N14 -> 1025.7022 | P14: =L14*Допущения!$C$25 -> 147.93493 | Q14: =L14*(1-Допущения!$C$25)+N14 -> 877.76726 | R14: =MAX(Допущения!$C$18,ROUNDUP(Q14/Допущения!$C$68+P14/Допущения!$C$69,0)) -> 13 | S14: =ROUNDUP(R14/Допущения!$C$48,0) -> 2 | T14: =L14*F14/(1+Допущения!$C$6) -> 2204861 | U14: =N14*Допущения!$C$28*E14/(1+Допущения!$C$6) -> 64380.306 | V14: =O14*Допущения!$C$26*Допущения!$C$27/(1+Допущения!$C$6) -> 126110.92 | W14: =T14+U14+V14 -> 2395352.2 | X14: =J14*Допущения!$C$37 -> 10000 | Y14: =(R14*Допущения!$C$47+S14*Допущения!$C$49)*D14*Допущения!$C$9 -> 1640520 | Z14: =(MAX(0,R14-R13)+R14*Допущения!$C$50/12)*Допущения!$C$51*D14 -> 162750 | AA14: =O14*(Допущения!$C$53+Допущения!$C$54)+(L14*F14+N14*Допущения!$C$28*E14)*Допущения!$C$13 -> 424213.84 | AB14: =(R14+S14)*Допущения!$C$52 -> 40500 | AC14: =SUMPRODUCT(Допущения!$B$84:$B$91,Допущения!$C$84:$C$91,--(Допущения!$D$84:$D$91<=A14))*D14*Допущения!$C$9 -> 1627500 | AD14: =(AC14+Y14)*Допущения!$C$14 -> 326802 | AE14: =Допущения!$C$55+Допущения!$C$56*O14/1000+Допущения!$C$57 -> 148205.62 | AF14: =SUMIF(Допущения!$B$95:$B$103,A14,Допущения!$C$95:$C$103) -> 500000 | AG14: 0 | AH14: =G14+SUM(X14:AG14) -> 5468222.7 | AI14: =W14-AH14 -> -3072870.5 | AJ14: =AJ13+AI14 -> -22886488 | AK14: =O14*Допущения!$C$58*Допущения!$C$59 -> 16924.086 | AL14: =T14*Допущения!$C$72 -> 111169.46 | AM14: =IF(MOD(A14,12)=0,INDEX($F$70:$F$74,B14),0) -> 0 | AN14: =AI14-AM14 -> -3072870.5 | AO14: =1/(1+Допущения!$C$74)^A14 -> 0.8614501 | AP14: =IF(AND(A14>Допущения!$C$19,MIN(AI14:AI$65)>0),A14,"") | AQ14: =IF(MIN(AJ14:AJ$65)>0,A14,"")
A15: 10 | B15: =INT((A15-1)/12)+1 -> 1 | C15: Масштабирование | D15: =(1+Допущения!$C$11)^(B15-1) -> 1 | E15: =(1+Допущения!$C$12)^(B15-1) -> 1 | F15: =Допущения!$C$71*E15 -> 2727.48 | G15: =MIN(G14*(1+Допущения!$C$33),Допущения!$C$34) -> 634749.73 | H15: =MIN(Допущения!$C$30,G15/Допущения!$C$29) -> 200 | I15: =MAX(0,G15-H15*Допущения!$C$29)/Допущения!$C$31 -> 44.633297 | J15: =IF(A15>=Допущения!$C$35,Допущения!$C$36,0) -> 20 | K15: =H15+I15+J15 -> 264.6333 | L15: =(L14-K14)*(1-Допущения!$C$44)+K14*(1-Допущения!$C$43)+K15 -> 1102.2092 | M15: =IF(A15>=Допущения!$C$38,Допущения!$C$73/Допущения!$C$42*MIN(Допущения!$C$42,A15-Допущения!$C$38+1),0) -> 20 | N15: =N14*(1-Допущения!$C$45)+M15 -> 58.679947 | O15: =L15+N15 -> 1160.8891 | P15: =L15*Допущения!$C$25 -> 165.33138 | Q15: =L15*(1-Допущения!$C$25)+N15 -> 995.55776 | R15: =MAX(Допущения!$C$18,ROUNDUP(Q15/Допущения!$C$68+P15/Допущения!$C$69,0)) -> 15 | S15: =ROUNDUP(R15/Допущения!$C$48,0) -> 2 | T15: =L15*F15/(1+Допущения!$C$6) -> 2464142.2 | U15: =N15*Допущения!$C$28*E15/(1+Допущения!$C$6) -> 95715.651 | V15: =O15*Допущения!$C$26*Допущения!$C$27/(1+Допущения!$C$6) -> 142732.27 | W15: =T15+U15+V15 -> 2702590.2 | X15: =J15*Допущения!$C$37 -> 10000 | Y15: =(R15*Допущения!$C$47+S15*Допущения!$C$49)*D15*Допущения!$C$9 -> 1848840 | Z15: =(MAX(0,R15-R14)+R15*Допущения!$C$50/12)*Допущения!$C$51*D15 -> 166250 | AA15: =O15*(Допущения!$C$53+Допущения!$C$54)+(L15*F15+N15*Допущения!$C$28*E15)*Допущения!$C$13 -> 479939.02 | AB15: =(R15+S15)*Допущения!$C$52 -> 45900 | AC15: =SUMPRODUCT(Допущения!$B$84:$B$91,Допущения!$C$84:$C$91,--(Допущения!$D$84:$D$91<=A15))*D15*Допущения!$C$9 -> 1966020 | AD15: =(AC15+Y15)*Допущения!$C$14 -> 381486 | AE15: =Допущения!$C$55+Допущения!$C$56*O15/1000+Допущения!$C$57 -> 149287.11 | AF15: =SUMIF(Допущения!$B$95:$B$103,A15,Допущения!$C$95:$C$103) -> 350000 | AG15: 0 | AH15: =G15+SUM(X15:AG15) -> 6032471.9 | AI15: =W15-AH15 -> -3329881.7 | AJ15: =AJ14+AI15 -> -26216370 | AK15: =O15*Допущения!$C$58*Допущения!$C$59 -> 19154.671 | AL15: =T15*Допущения!$C$72 -> 124242.47 | AM15: =IF(MOD(A15,12)=0,INDEX($F$70:$F$74,B15),0) -> 0 | AN15: =AI15-AM15 -> -3329881.7 | AO15: =1/(1+Допущения!$C$74)^A15 -> 0.84729272 | AP15: =IF(AND(A15>Допущения!$C$19,MIN(AI15:AI$65)>0),A15,"") | AQ15: =IF(MIN(AJ15:AJ$65)>0,A15,"")
A16: 11 | B16: =INT((A16-1)/12)+1 -> 1 | C16: Масштабирование | D16: =(1+Допущения!$C$11)^(B16-1) -> 1 | E16: =(1+Допущения!$C$12)^(B16-1) -> 1 | F16: =Допущения!$C$71*E16 -> 2727.48 | G16: =MIN(G15*(1+Допущения!$C$33),Допущения!$C$34) -> 685529.71 | H16: =MIN(Допущения!$C$30,G16/Допущения!$C$29) -> 200 | I16: =MAX(0,G16-H16*Допущения!$C$29)/Допущения!$C$31 -> 51.403961 | J16: =IF(A16>=Допущения!$C$35,Допущения!$C$36,0) -> 20 | K16: =H16+I16+J16 -> 271.40396 | L16: =(L15-K15)*(1-Допущения!$C$44)+K15*(1-Допущения!$C$43)+K16 -> 1213.9854 | M16: =IF(A16>=Допущения!$C$38,Допущения!$C$73/Допущения!$C$42*MIN(Допущения!$C$42,A16-Допущения!$C$38+1),0) -> 20 | N16: =N15*(1-Допущения!$C$45)+M16 -> 77.506348 | O16: =L16+N16 -> 1291.4918 | P16: =L16*Допущения!$C$25 -> 182.09781 | Q16: =L16*(1-Допущения!$C$25)+N16 -> 1109.394 | R16: =MAX(Допущения!$C$18,ROUNDUP(Q16/Допущения!$C$68+P16/Допущения!$C$69,0)) -> 16 | S16: =ROUNDUP(R16/Допущения!$C$48,0) -> 2 | T16: =L16*F16/(1+Допущения!$C$6) -> 2714033.6 | U16: =N16*Допущения!$C$28*E16/(1+Допущения!$C$6) -> 126424.29 | V16: =O16*Допущения!$C$26*Допущения!$C$27/(1+Допущения!$C$6) -> 158789.97 | W16: =T16+U16+V16 -> 2999247.9 | X16: =J16*Допущения!$C$37 -> 10000 | Y16: =(R16*Допущения!$C$47+S16*Допущения!$C$49)*D16*Допущения!$C$9 -> 1953000 | Z16: =(MAX(0,R16-R15)+R16*Допущения!$C$50/12)*Допущения!$C$51*D16 -> 98000 | AA16: =O16*(Допущения!$C$53+Допущения!$C$54)+(L16*F16+N16*Допущения!$C$28*E16)*Допущения!$C$13 -> 533770.95 | AB16: =(R16+S16)*Допущения!$C$52 -> 48600 | AC16: =SUMPRODUCT(Допущения!$B$84:$B$91,Допущения!$C$84:$C$91,--(Допущения!$D$84:$D$91<=A16))*D16*Допущения!$C$9 -> 1966020 | AD16: =(AC16+Y16)*Допущения!$C$14 -> 391902 | AE16: =Допущения!$C$55+Допущения!$C$56*O16/1000+Допущения!$C$57 -> 150331.93 | AF16: =SUMIF(Допущения!$B$95:$B$103,A16,Допущения!$C$95:$C$103) -> 350000 | AG16: 0 | AH16: =G16+SUM(X16:AG16) -> 6187154.6 | AI16: =W16-AH16 -> -3187906.7 | AJ16: =AJ15+AI16 -> -29404276 | AK16: =O16*Допущения!$C$58*Допущения!$C$59 -> 21309.614 | AL16: =T16*Допущения!$C$72 -> 136842.03 | AM16: =IF(MOD(A16,12)=0,INDEX($F$70:$F$74,B16),0) -> 0 | AN16: =AI16-AM16 -> -3187906.7 | AO16: =1/(1+Допущения!$C$74)^A16 -> 0.833368 | AP16: =IF(AND(A16>Допущения!$C$19,MIN(AI16:AI$65)>0),A16,"") | AQ16: =IF(MIN(AJ16:AJ$65)>0,A16,"")
A17: 12 | B17: =INT((A17-1)/12)+1 -> 1 | C17: Масштабирование | D17: =(1+Допущения!$C$11)^(B17-1) -> 1 | E17: =(1+Допущения!$C$12)^(B17-1) -> 1 | F17: =Допущения!$C$71*E17 -> 2727.48 | G17: =MIN(G16*(1+Допущения!$C$33),Допущения!$C$34) -> 740372.08 | H17: =MIN(Допущения!$C$30,G17/Допущения!$C$29) -> 200 | I17: =MAX(0,G17-H17*Допущения!$C$29)/Допущения!$C$31 -> 58.716278 | J17: =IF(A17>=Допущения!$C$35,Допущения!$C$36,0) -> 20 | K17: =H17+I17+J17 -> 278.71628 | L17: =(L16-K16)*(1-Допущения!$C$44)+K16*(1-Допущения!$C$43)+K17 -> 1322.3038 | M17: =IF(A17>=Допущения!$C$38,Допущения!$C$73/Допущения!$C$42*MIN(Допущения!$C$42,A17-Допущения!$C$38+1),0) -> 20 | N17: =N16*(1-Допущения!$C$45)+M17 -> 95.956221 | O17: =L17+N17 -> 1418.26 | P17: =L17*Допущения!$C$25 -> 198.34557 | Q17: =L17*(1-Допущения!$C$25)+N17 -> 1219.9145 | R17: =MAX(Допущения!$C$18,ROUNDUP(Q17/Допущения!$C$68+P17/Допущения!$C$69,0)) -> 18 | S17: =ROUNDUP(R17/Допущения!$C$48,0) -> 2 | T17: =L17*F17/(1+Допущения!$C$6) -> 2956194.4 | U17: =N17*Допущения!$C$28*E17/(1+Допущения!$C$6) -> 156518.75 | V17: =O17*Допущения!$C$26*Допущения!$C$27/(1+Допущения!$C$6) -> 174376.23 | W17: =T17+U17+V17 -> 3287089.4 | X17: =J17*Допущения!$C$37 -> 10000 | Y17: =(R17*Допущения!$C$47+S17*Допущения!$C$49)*D17*Допущения!$C$9 -> 2161320 | Z17: =(MAX(0,R17-R16)+R17*Допущения!$C$50/12)*Допущения!$C$51*D17 -> 171500 | AA17: =O17*(Допущения!$C$53+Допущения!$C$54)+(L17*F17+N17*Допущения!$C$28*E17)*Допущения!$C$13 -> 586020.09 | AB17: =(R17+S17)*Допущения!$C$52 -> 54000 | AC17: =SUMPRODUCT(Допущения!$B$84:$B$91,Допущения!$C$84:$C$91,--(Допущения!$D$84:$D$91<=A17))*D17*Допущения!$C$9 -> 1966020 | AD17: =(AC17+Y17)*Допущения!$C$14 -> 412734 | AE17: =Допущения!$C$55+Допущения!$C$56*O17/1000+Допущения!$C$57 -> 151346.08 | AF17: =SUMIF(Допущения!$B$95:$B$103,A17,Допущения!$C$95:$C$103) -> 300000 | AG17: 0 | AH17: =G17+SUM(X17:AG17) -> 6553312.3 | AI17: =W17-AH17 -> -3266222.9 | AJ17: =AJ16+AI17 -> -32670499 | AK17: =O17*Допущения!$C$58*Допущения!$C$59 -> 23401.29 | AL17: =T17*Допущения!$C$72 -> 149051.82 | AM17: =IF(MOD(A17,12)=0,INDEX($F$70:$F$74,B17),0) -> 0 | AN17: =AI17-AM17 -> -3266222.9 | AO17: =1/(1+Допущения!$C$74)^A17 -> 0.81967213 | AP17: =IF(AND(A17>Допущения!$C$19,MIN(AI17:AI$65)>0),A17,"") | AQ17: =IF(MIN(AJ17:AJ$65)>0,A17,"")
A18: 13 | B18: =INT((A18-1)/12)+1 -> 2 | C18: Масштабирование | D18: =(1+Допущения!$C$11)^(B18-1) -> 1.08 | E18: =(1+Допущения!$C$12)^(B18-1) -> 1.07 | F18: =Допущения!$C$71*E18 -> 2918.4036 | G18: =MIN(G17*(1+Допущения!$C$33),Допущения!$C$34) -> 799601.85 | H18: =MIN(Допущения!$C$30,G18/Допущения!$C$29) -> 200 | I18: =MAX(0,G18-H18*Допущения!$C$29)/Допущения!$C$31 -> 66.61358 | J18: =IF(A18>=Допущения!$C$35,Допущения!$C$36,0) -> 20 | K18: =H18+I18+J18 -> 286.61358 | L18: =(L17-K17)*(1-Допущения!$C$44)+K17*(1-Допущения!$C$43)+K18 -> 1427.8797 | M18: =IF(A18>=Допущения!$C$38,Допущения!$C$73/Допущения!$C$42*MIN(Допущения!$C$42,A18-Допущения!$C$38+1),0) -> 20 | N18: =N17*(1-Допущения!$C$45)+M18 -> 114.0371 | O18: =L18+N18 -> 1541.9168 | P18: =L18*Допущения!$C$25 -> 214.18195 | Q18: =L18*(1-Допущения!$C$25)+N18 -> 1327.7348 | R18: =MAX(Допущения!$C$18,ROUNDUP(Q18/Допущения!$C$68+P18/Допущения!$C$69,0)) -> 19 | S18: =ROUNDUP(R18/Допущения!$C$48,0) -> 2 | T18: =L18*F18/(1+Допущения!$C$6) -> 3415679.7 | U18: =N18*Допущения!$C$28*E18/(1+Допущения!$C$6) -> 199032.12 | V18: =O18*Допущения!$C$26*Допущения!$C$27/(1+Допущения!$C$6) -> 189579.93 | W18: =T18+U18+V18 -> 3804291.7 | X18: =J18*Допущения!$C$37 -> 10000 | Y18: =(R18*Допущения!$C$47+S18*Допущения!$C$49)*D18*Допущения!$C$9 -> 2446718.4 | Z18: =(MAX(0,R18-R17)+R18*Допущения!$C$50/12)*Допущения!$C$51*D18 -> 111510 | AA18: =O18*(Допущения!$C$53+Допущения!$C$54)+(L18*F18+N18*Допущения!$C$28*E18)*Допущения!$C$13 -> 642178.7 | AB18: =(R18+S18)*Допущения!$C$52 -> 56700 | AC18: =SUMPRODUCT(Допущения!$B$84:$B$91,Допущения!$C$84:$C$91,--(Допущения!$D$84:$D$91<=A18))*D18*Допущения!$C$9 -> 2123301.6 | AD18: =(AC18+Y18)*Допущения!$C$14 -> 457002 | AE18: =Допущения!$C$55+Допущения!$C$56*O18/1000+Допущения!$C$57 -> 152335.33 | AF18: =SUMIF(Допущения!$B$95:$B$103,A18,Допущения!$C$95:$C$103) -> 0 | AG18: 0 | AH18: =G18+SUM(X18:AG18) -> 6799347.9 | AI18: =W18-AH18 -> -2995056.1 | AJ18: =AJ17+AI18 -> -35665555 | AK18: =O18*Допущения!$C$58*Допущения!$C$59 -> 25441.627 | AL18: =T18*Допущения!$C$72 -> 172219.14 | AM18: =IF(MOD(A18,12)=0,INDEX($F$70:$F$74,B18),0) -> 0 | AN18: =AI18-AM18 -> -2995056.1 | AO18: =1/(1+Допущения!$C$74)^A18 -> 0.80620134 | AP18: =IF(AND(A18>Допущения!$C$19,MIN(AI18:AI$65)>0),A18,"") | AQ18: =IF(MIN(AJ18:AJ$65)>0,A18,"")
